test_crit (__main__.TestCharacter) ... ERROR
test_init (__main__.TestCharacter) ... ERROR
test_name (__main__.TestCharacter) ... ERROR
test_weapon (__main__.TestCharacter) ... ERROR
test_init (__main__.TestWeapon) ... ERROR
test_name (__main__.TestWeapon) ... ERROR
test_unarmed (__main__.TestWeapon) ... ERROR

======================================================================
ERROR: test_crit (__main__.TestCharacter)
----------------------------------------------------------------------
Traceback (most recent call last):
  File "/Users/samimniazi/Desktop/inf1007/c03-ch11-1-exercices-SamimNiazi/test_exercice.py", line 38, in setUp
    self.hp_only =  Character("hp_only",  69,  1,  1,  1)
TypeError: Character() takes no arguments

======================================================================
ERROR: test_init (__main__.TestCharacter)
----------------------------------------------------------------------
Traceback (most recent call last):
  File "/Users/samimniazi/Desktop/inf1007/c03-ch11-1-exercices-SamimNiazi/test_exercice.py", line 38, in setUp
    self.hp_only =  Character("hp_only",  69,  1,  1,  1)
TypeError: Character() takes no arguments

======================================================================
ERROR: test_name (__main__.TestCharacter)
----------------------------------------------------------------------
Traceback (most recent call last):
  File "/Users/samimniazi/Desktop/inf1007/c03-ch11-1-exercices-SamimNiazi/test_exercice.py", line 38, in setUp
    self.hp_only =  Character("hp_only",  69,  1,  1,  1)
TypeError: Character() takes no arguments

======================================================================
ERROR: test_weapon (__main__.TestCharacter)
----------------------------------------------------------------------
Traceback (most recent call last):
  File "/Users/samimniazi/Desktop/inf1007/c03-ch11-1-exercices-SamimNiazi/test_exercice.py", line 38, in setUp
    self.hp_only =  Character("hp_only",  69,  1,  1,  1)
TypeError: Character() takes no arguments

======================================================================
ERROR: test_init (__main__.TestWeapon)
----------------------------------------------------------------------
Traceback (most recent call last):
  File "/Users/samimniazi/Desktop/inf1007/c03-ch11-1-exercices-SamimNiazi/test_exercice.py", line 16, in setUp
    self.w1 = Weapon("w1", 1, 69)
TypeError: Weapon() takes no arguments

======================================================================
ERROR: test_name (__main__.TestWeapon)
----------------------------------------------------------------------
Traceback (most recent call last):
  File "/Users/samimniazi/Desktop/inf1007/c03-ch11-1-exercices-SamimNiazi/test_exercice.py", line 16, in setUp
    self.w1 = Weapon("w1", 1, 69)
TypeError: Weapon() takes no arguments

======================================================================
ERROR: test_unarmed (__main__.TestWeapon)
----------------------------------------------------------------------
Traceback (most recent call last):
  File "/Users/samimniazi/Desktop/inf1007/c03-ch11-1-exercices-SamimNiazi/test_exercice.py", line 16, in setUp
    self.w1 = Weapon("w1", 1, 69)
TypeError: Weapon() takes no arguments

----------------------------------------------------------------------
Ran 7 tests in 0.002s

FAILED (errors=7)
